<?xml version="1.0"?>
<robot name="crx-10">
  <link name="base_link">
    <inertial>
      <origin rpy = "0 0 0" xyz = "0 0 0" />
      <mass value = "0.0001" />
      <inertia ixx = "0.0001" ixy = "0" ixz = "0" iyy = "0.0001" iyz = "0" izz = "0.0001" />
    </inertial>
  </link>

  <joint name="base_stand" type="fixed" >
    <parent link = "base_link" />
    <child link = "stand" />
    <origin rpy = "0 0 0" xyz = "0.000 0.000 0.000" />
  </joint>
  <link name="stand">
    <contact>
      <lateral_friction value = "100" />
    </contact>
    <inertial>
      <origin rpy = "0 0 0" xyz = "0.000 0.000 0.06125" />
        <mass value = "5000" />
        <inertia ixx = "54.5" ixy = "0" ixz = "0" iyy = "54.5" iyz = "0" izz = "76.6" />
    </inertial>
    <visual>
      <origin rpy="0 0 0" xyz="0 0 0.000"/>
      <geometry>
        <!-- <cylinder radius="0.095" length="0.1225"/> -->
        <mesh filename="package://crx10_description/mesh/stl/stand.stl"/>
      </geometry>      
      <material name="Black">
        <color rgba="0.3 0.3 0.3 1" />
      </material>
    </visual>
    <collision>
      <origin rpy = "0 0 0" xyz = "0.000 0.000 0.000" />
      <geometry>
        <!-- <cylinder radius="0.095" length="0.1225"/> -->
        <mesh filename="package://crx10_description/mesh/stl/stand.stl"/>
      </geometry>
    </collision>
  </link>

  <joint name="stand_arm1" type="revolute" >
    <parent link = "stand" />
    <child link = "arm1" />
    <origin rpt = "0 0 0" xyz = "0 0 0.1225" />
    <axis xyz = "0 0 1" />
    <limit effort="10000.0" lower="-3.315" upper="3.315" velocity="2.09"/>
  </joint>
  <link name="arm1">
    <inertial>
      <origin rpy = "0 0 0" xyz = "0.000 0.000 0.06125" />
        <mass value = "7.5" />
        <inertia ixx = "0.066441" ixy = "0" ixz = "0" iyy = "0.075957" iyz = "0" izz = "0.059516" />
    </inertial>
    <visual>
      <origin rpy="0 0 0" xyz="0 0.000 0.000"/>
      <geometry>
        <!-- <box size="0.190 0.190 0.1225"/> -->
        <mesh filename="package://crx10_description/mesh/stl/arm1.stl"/>
      </geometry>
      <material name="Green">
        <color rgba="0.2 0.8 0.2 1" />
      </material>
    </visual>
    <collision>
      <origin rpy = "0 0 0" xyz = "0.000 0.000 0.000" />
      <geometry>
        <!-- <box size = "0.190 0.190 0.1225" /> -->
        <mesh filename="package://crx10_description/mesh/stl/arm1.stl"/>
      </geometry>
    </collision>
  </link>

  <joint name="arm1_arm2" type="revolute" >
    <parent link = "arm1" />
    <child link = "arm2" />
    <!-- <origin rpy = "-1.57075 0 -1.57075" xyz = "0.000 -0.190 0.000" /> -->
    <origin rpy = "0 -1.5707963267948966 -1.5707963267948966" xyz = "0.000 -0.095 0.1225" />
    <axis xyz = "0 0 1" />
    <limit effort="10000.0" lower="-3.14" upper="3.14" velocity="2.09"/>
  </joint>
  <link name="arm2">
    <inertial>
      <!-- 0.355 - 0.06125 = 0.29375 -->
      <origin rpy = "0 0 0" xyz = "0.000 0.000 -0.000" />
        <mass value = "10" />
        <inertia ixx = "0.17333" ixy = "0" ixz = "0" iyy = "0.18008" iyz = "0" izz = "0.03075" />
    </inertial>
    <visual>
      <origin rpy="0 0 0" xyz="0.000 0.000 -0.000"/>
      <geometry>
        <!-- <box size="0.710 0.190 0.190"/> -->
        <mesh filename="package://crx10_description/mesh/stl/arm2.stl"/>
      </geometry>
      <material name="Gray">
        <color rgba="0.95 0.95 0.95 1" />
      </material>
    </visual>
    <collision>
      <origin rpy = "0 0 0" xyz = "0.000 0.000 -0.000" />
      <geometry>
        <!-- <box size="0.710 0.190 0.190"/> -->
        <mesh filename="package://crx10_description/mesh/stl/arm2.stl"/>
      </geometry>
    </collision>
  </link>

  <joint name="arm2_arm3" type="revolute" >
    <parent link = "arm2" />
    <child link = "arm3" />
    <origin rpy = "3.1415927 0 0" xyz = "0.710 0.000 0.000" />
    <axis xyz = "0 0 1" />
    <limit effort="10000.0" lower="-4.975" upper="4.975" velocity="3.15"/>
  </joint>
  <link name="arm3">
    <inertial>
      <origin rpy = "0 0 0" xyz = "0.000 0.000 0.000" />
        <mass value = "7.5" />
        <inertia ixx = "0.044381" ixy = "0" ixz = "0" iyy = "0.044381" iyz = "0" izz = "0.01250" />
    </inertial>
    <visual>
      <origin rpy="0 0 0" xyz="0 0 0.000"/>
      <geometry>
        <!-- <box size="0.150 0.150 0.150"/> -->
        <mesh filename="package://crx10_description/mesh/stl/arm3.stl"/>
      </geometry>
      <material name="Green">
      </material>
    </visual>
    <collision>
      <origin rpy = "0 0 0" xyz = "0.000 0.000 0.000" />
      <geometry>
        <!-- <box size="0.150 0.150 0.150"/> -->
        <mesh filename="package://crx10_description/mesh/stl/arm3.stl"/>
      </geometry>
    </collision>
  </link>


  <joint name="arm3_arm4" type="revolute" >
    <parent link = "arm3" />
    <child link = "arm4" />
    <axis xyz="0 0 1"/>
    <origin rpy = "1.5707963267948966 0 -3.1415927" xyz = "0.000 -0.075 -0.095" />
    <!-- <origin rpy = "0 -1.5707963267948966 -1.5707963267948966" xyz = "0.000 0.075 0.000" /> -->
    <limit effort="10000.0" lower="-3.315" upper="3.315" velocity="3.14"/>
  </joint>
  <link name="arm4">
    <inertial>
      <origin rpy = "0 0 0" xyz = "0.000 0.000 0.270" />
        <mass value = "5" />
        <inertia ixx = "0.014833" ixy = "0" ixz = "0" iyy = "0.014833" iyz = "0" izz = "0.0083333" />
    </inertial>
    <visual>
      <origin rpy="0 0 0" xyz="0 0 0.000"/>
      <geometry>
        <!-- <box size="0.150 0.150 0.540"/> -->
        <mesh filename="package://crx10_description/mesh/stl/arm4.stl"/>
      </geometry>
      <material name="Gray">
      </material>
    </visual>
    <collision>
      <origin rpy = "0 0 0" xyz = "0.000 0.000 0.000" />
      <geometry>
        <!-- <box size = "0.150 0.150 0.540" /> -->
        <mesh filename="package://crx10_description/mesh/stl/arm4.stl"/>
      </geometry>
    </collision>
  </link>

  <joint name="arm4_arm5" type="revolute" >
    <parent link = "arm4" />
    <child link = "arm5" />
    <axis xyz = "0 0 1" />
    <origin rpy = "-1.5707963267948966 -1.5707963267948966 0" xyz = "0.000 0.075 -0.465" />
    <limit effort="10000.0" lower="-3.14" upper="3.14" velocity="3.14"/>
  </joint>
  <link name="arm5">
    <inertial>
      <origin rpy = "0 0 0" xyz = "0.000 0.000 -0.050" />
        <mass value = "2.5" />
        <inertia ixx = "0.0020833" ixy = "0" ixz = "0" iyy = "0.0015208" iyz = "0" izz = "0.00093750" />
    </inertial>
    <visual>
      <origin rpy="0 0 0" xyz="0.000 0.000 -0.000"/>
      <geometry>
        <!-- <box size="0.100 0.100 0.100"/> -->
        <mesh filename="package://crx10_description/mesh/stl/arm5.stl"/>
      </geometry>
      <material name="Green">
      </material>
    </visual>
    <collision>
      <origin rpy = "0 0 0" xyz = "0.000 0.000 -0.000" />
      <geometry>
        <!-- <box size = "0.100 0.100 0.100" /> -->
        <mesh filename="package://crx10_description/mesh/stl/arm5.stl"/>
      </geometry>
    </collision>
  </link>

  <joint name="arm5_arm6" type="revolute" >
    <parent link = "arm5" />
    <child link = "arm6" />
    <origin rpy = "1.5707963267948966 0 1.5707963267948966" xyz = "-0.100 0.000 0.075" />
    <axis xyz="0 0 1"/>
    <limit effort="10000.0" lower="-3.925" upper="3.925" velocity="3.14"/>
  </joint>
  <link name="arm6">
    <inertial>
      <origin rpy = "0 0 0" xyz = "0.000 0.000 0.096" />
        <mass value = "0.5" />
        <inertia ixx = "0.000032292" ixy = "0" ixz = "0" iyy = "0.000032292" iyz = "0" izz = "0.00005625" />
    </inertial>
    <visual>
      <origin rpy="0 0 0" xyz="0 0 0"/>
      <geometry>
        <!-- <cylinder radius="0.050" length="0.060"/> -->
        <mesh filename="package://crx10_description/mesh/stl/arm6.stl"/>
      </geometry>
      <material name="Black">
      </material>
    </visual>
    <collision>
      <origin rpy = "0 0 0" xyz="0 0 0"/>
      <geometry>
        <!-- <cylinder radius="0.015" length="0.060"/> -->
        <mesh filename="package://crx10_description/mesh/stl/arm6.stl"/>
      </geometry>
    </collision>
  </link>
  
  <joint name="arm6_ee" type="fixed" >
    <parent link = "arm6" />
    <child link = "ee_link" />
    <origin rpy = "0 0 0" xyz = "0.000 0.000 -0.126" />
  </joint>
  <link name="ee_link">
    <inertial>
      <origin rpy = "0 0 0" xyz = "0.000 0.000 0.066" />
        <mass value = "0.5" />
        <inertia ixx = "0.000032292" ixy = "0" ixz = "0" iyy = "0.000032292" iyz = "0" izz = "0.00005625" />
    </inertial>
    <visual>
      <origin rpy="0 0 0" xyz="0 0 0"/>
      <geometry>
        <!-- <cylinder radius="0.000" length="0.000"/> -->
        <mesh filename="package://crx10_description/mesh/stl/tool.stl"/>
      </geometry>
      <material name="Blue">
        <color rgba="0.15 0.15 0.85 1" />
      </material>
    </visual>
    <collision>
      <origin rpy = "0 0 0" xyz="0 0 0"/>
      <geometry>
        <!-- <cylinder radius="0.000" length="0.000"/> -->
        <mesh filename="package://crx10_description/mesh/stl/tool.stl"/>
      </geometry>
    </collision>
  </link>

  <joint name="ee_tcp" type="fixed" >
    <parent link = "ee_link" />
    <child link = "tcp" />
    <origin rpy = "0 3.1415927 -0.785398175" xyz = "-0.105 0.100 -0.189" />
  </joint>
  <link name="tcp">
    <inertial>
      <origin rpy = "0 0 0" xyz = "0.000 0.000 0.030" />
        <mass value = "0.5" />
        <inertia ixx = "0.000032292" ixy = "0" ixz = "0" iyy = "0.000032292" iyz = "0" izz = "0.00005625" />
    </inertial>
    <!-- <visual>
      <origin rpy="0 0 0" xyz="0 0 0"/>
      <geometry>
        <cylinder radius="0.000" length="0.000"/>
      </geometry>
      <material name="Blue">
        <color rgba="0.15 0.15 0.75" />
      </material>
    </visual>
    <collision>
      <origin rpy = "0 0 0" xyz="0 0 0"/>
      <geometry>
        <cylinder radius="0.000" length="0.000"/>
      </geometry>
    </collision> -->
  </link>

  <!-- <link name="gripper1">
    <inertial>
      <origin rpy = "0 0 0" xyz = "0.000 0.000 0.005" />
        <mass value = "0.020" />
        <inertia ixx = "0.01" ixy = "0" ixz = "0" iyy = "0.01" iyz = "0" izz = "0.01" />
    </inertial>
    <visual>
      <origin rpy="0 0 0" xyz="0 0 0.005"/>
      <geometry>
        <box size="0.04 0.01 0.01"/>
      </geometry>
      <material name="Black">
      </material>
    </visual>
    <collision>
      <origin rpy = "0 0 0" xyz = "0.000 0.000 0.005" />
      <geometry>
        <box size = "0.04 0.01 0.010" />
      </geometry>
    </collision>
  </link>
  <joint name="arm6_gripper1" type="fixed" >
    <parent link = "arm6" />
    <child link = "gripper1" />
    <origin rpy = "0 0 0" xyz = "0.000 0.000 0.010" />
  </joint>
  <link name="gripper2">
    <contact>
      <lateral_friction value = "10" />
    </contact>
    <inertial>
      <origin rpy = "0 0 0" xyz = "0.000 0.000 0.0075" />
        <mass value = "0.003" />
        <inertia ixx = "0.01" ixy = "0" ixz = "0" iyy = "0.005" iyz = "0" izz = "0.005" />
    </inertial>
    <visual>
      <origin rpy="0 0 0" xyz="0 0 0.0075"/>
      <geometry>
        <box size="0.005 0.01 0.015"/>
      </geometry>
      <material name="Black">
      </material>
    </visual>
    <collision>
      <origin rpy = "0 0 0" xyz = "0.000 0.000 0.0075" />
      <geometry>
        <box size = "0.005 0.010 0.015" />
      </geometry>
    </collision>
  </link>
  <joint name="gripper1_gripper2" type="prismatic" >
    <parent link = "gripper1" />
    <child link = "gripper2" />
    <origin rpy = "0 0 0" xyz = "-0.0175 0.000 0.01" />
    <limit effort="10000.0" lower="0" upper="0.015" velocity="0.5"/>
  </joint>
  <link name="gripper3">
    <contact>
      <lateral_friction value = "10" />
    </contact>
    <inertial>
      <origin rpy = "0 0 0" xyz = "0.000 0.000 0.0075" />
        <mass value = "0.003" />
        <inertia ixx = "0.01" ixy = "0" ixz = "0" iyy = "0.005" iyz = "0" izz = "0.005" />
    </inertial>
    <visual>
      <origin rpy="0 0 0" xyz="0 0 0.0075"/>
      <geometry>
        <box size="0.005 0.01 0.015"/>
      </geometry>
      <material name="Black">
      </material>
    </visual>
    <collision>
      <origin rpy = "0 0 0" xyz = "0.000 0.000 0.0075" />
      <geometry>
        <box size = "0.005 0.010 0.015" />
      </geometry>
    </collision>
  </link>
  <joint name="gripper1_gripper3" type="prismatic" >
    <parent link = "gripper1" />
    <child link = "gripper3" />
    <origin rpy = "0 0 0" xyz = "0.0175 0.000 0.01" />
    <limit effort="10000.0" lower="-0.015" upper="0" velocity="0.5"/>
  </joint> -->
</robot>